Workbook

Sheet 薬品マスタ
A1: 薬品ID | B1: 薬品名 | C1: 成分名 | D1: 用法用量 | E1: 区分 | F1: 簡易懸濁可否 | G1: 粉砕可否 | H1: 脱カプセル可否 | I1: 薬効分類（大） | J1: 薬品カナ | K1: 先発/後発区分 | L1: 後発名 | M1: 先発名 | N1: 採用区分 | O1: 採用状態フラグ | P1: 表示フラグ | Q1: 改訂日 | R1: 切り替え元ID | S1: 備考欄 | T1: 薬効分類（中） | U1: 薬効分類（小） | V1: 列1 | W1: 薬剤科コメント
A2: DR0001 | B2: ユナシン錠375ｍｇ | C2: スルタミシリントシル酸塩水和物 | D2: 1回1錠1日2～3回 | E2: 内服薬 | F2: 〇 | G2: 〇 | I2: 1.抗菌抗薬 | J2: ユナシンジョウ | K2: 先発 | L2: =IFERROR(_xlfn.TEXTJOIN(" / ",TRUE, IF($R$2:$R$503=A2,$B$2:$B$503,"") ),"") | M2: =IFERROR(INDEX($B$2:$B$502, MATCH(R2, $A$2:$A$502, 0)), "") | N2: 採用 | O2: =IF(N2="採用",1,IF(N2="限定",2,IF(N2="削除",0,""))) -> 1 | P2: =IF(N2="削除",0,1) -> 1 | Q2: 46198 | T2: 01.広範囲ペニシリン系 | V2: =COUNTIF(R:R,"DR0250") -> 1
A3: DR0002 | B3: セフジトレンピボキシル錠100ｍｇ「SW」 | C3: セフジトレンピボキシル | D3: 1回1錠1日3回 | E3: 内服薬 | F3: 〇 | G3: 〇 | I3: 1.抗菌抗薬 | J3: セフジトレンピボキシルジョウ100mgサワイ | K3: 後発 | L3: =IFERROR(_xlfn.TEXTJOIN(" / ",TRUE, IF($R$2:$R$503=A3,$B$2:$B$503,"") ),"") | M3: =IFERROR(INDEX($B$2:$B$502, MATCH(R3, $A$2:$A$502, 0)), "") | N3: 採用 | O3: =IF(N3="採用",1,IF(N3="限定",2,IF(N3="削除",0,""))) -> 1 | P3: =IF(N3="削除",0,1) -> 1 | Q3: 46198 | T3: 02.セフェム系 | U3: 01.第３世代 | V3: =COUNTIF(R:R,"DR0250") -> 1
A4: DR0003 | B4: セフカペンピボキシル塩酸塩錠100mg「SW」 | C4: セフカペンピボキシル塩酸塩 | D4: 1回1錠、1日3回。難治性には1回2錠 | E4: 内服薬 | F4: 〇 | G4: 〇 | I4: 1.抗菌抗薬 | J4: セフカペンピボキシルエンサンエン100mgサワイ | K4: 後発 | L4: =IFERROR(_xlfn.TEXTJOIN(" / ",TRUE, IF($R$2:$R$503=A4,$B$2:$B$503,"") ),"") | M4: =IFERROR(INDEX($B$2:$B$502, MATCH(R4, $A$2:$A$502, 0)), "") | N4: 採用 | O4: =IF(N4="採用",1,IF(N4="限定",2,IF(N4="削除",0,""))) -> 1 | P4: =IF(N4="削除",0,1) -> 1 | Q4: 46198 | T4: 02.セフェム系 | U4: 01.第３世代 | V4: =COUNTIF(R:R,"DR0250") -> 1
A5: DR0004 | B5: カナマイシンカプセル250mg「明治」 | C5: カナマイシン硫酸塩 | D5: 1日0.5～1g、1日4回 | E5: 内服薬 | F5: 〇 | H5: 〇 | I5: 1.抗菌抗薬 | J5: カナマイシンカプセル250mgメイジ | K5: 後発 | L5: =IFERROR(_xlfn.TEXTJOIN(" / ",TRUE, IF($R$2:$R$503=A5,$B$2:$B$503,"") ),"") | M5: =IFERROR(INDEX($B$2:$B$502, MATCH(R5, $A$2:$A$502, 0)), "") | N5: 採用 | O5: =IF(N5="採用",1,IF(N5="限定",2,IF(N5="削除",0,""))) -> 1 | P5: =IF(N5="削除",0,1) -> 1 | Q5: 46198 | T5: 03.アミノグリコシド系 | V5: =COUNTIF(R:R,"DR0250") -> 1
A6: DR0005 | B6: エリスロシンドライシロップW20％ | C6: エリスロマイシンエチルコハク酸エステル | D6: 1回800～1200mg、4～6回 | E6: 内服薬 | F6: 〇 | I6: 1.抗菌抗薬 | J6: エリスロシンドライシロップW10％ | K6: 後発 | L6: =IFERROR(_xlfn.TEXTJOIN(" / ",TRUE, IF($R$2:$R$503=A6,$B$2:$B$503,"") ),"") | M6: =IFERROR(INDEX($B$2:$B$502, MATCH(R6, $A$2:$A$502, 0)), "") | N6: 採用 | O6: =IF(N6="採用",1,IF(N6="限定",2,IF(N6="削除",0,""))) -> 1 | P6: =IF(N6="削除",0,1) -> 1 | Q6: 46198 | T6: 04.マクロライド系 | V6: =COUNTIF(R:R,"DR0250") -> 1
A7: DR0006 | B7: クラリスロマイシン錠200mg「大正」 | C7: クラリスロマイシン | D7: 1回1錠、1日2回 | E7: 内服薬 | F7: 〇 | G7: 〇 | I7: 1.抗菌抗薬 | J7: クラリスロマイシンジョウ200mgタイショウ | K7: 後発 | L7: =IFERROR(_xlfn.TEXTJOIN(" / ",TRUE, IF($R$2:$R$503=A7,$B$2:$B$503,"") ),"") | M7: =IFERROR(INDEX($B$2:$B$502, MATCH(R7, $A$2:$A$502, 0)), "") | N7: 採用 | O7: =IF(N7="採用",1,IF(N7="限定",2,IF(N7="削除",0,""))) -> 1 | P7: =IF(N7="削除",0,1) -> 1 | Q7: 46198 | T7: 04.マクロライド系 | V7: =COUNTIF(R:R,"DR0250") -> 1
A8: DR0007 | B8: ジスロマック錠250ｍｇ | C8: アジスロマイシン | D8: 1日1回500mg3日間 | E8: 内服薬 | F8: 〇 | G8: △ | I8: 1.抗菌抗薬 | J8: ジスロマックジョウ250mg | K8: 先発 | L8: =IFERROR(_xlfn.TEXTJOIN(" / ",TRUE, IF($R$2:$R$503=A8,$B$2:$B$503,"") ),"") | M8: =IFERROR(INDEX($B$2:$B$502, MATCH(R8, $A$2:$A$502, 0)), "") | N8: 採用 | O8: =IF(N8="採用",1,IF(N8="限定",2,IF(N8="削除",0,""))) -> 1 | P8: =IF(N8="削除",0,1) -> 1 | Q8: 46198 | T8: 04.マクロライド系 | V8: =COUNTIF(R:R,"DR0250") -> 1 | W8: 【調剤注意】苦味ありのため条件付き粉砕可
A9: DR0008 | B9: ミノマイシンカプセル100mg | C9: ミノサイクリン塩酸塩 | D9: 初回100～200mg、以降12～24時間毎に100mg内服 | E9: 内服薬 | F9: 〇 | H9: 〇 | I9: 1.抗菌抗薬 | J9: ミノマイシンカプセル | K9: 先発 | L9: =IFERROR(_xlfn.TEXTJOIN(" / ",TRUE, IF($R$2:$R$503=A9,$B$2:$B$503,"") ),"") | M9: =IFERROR(INDEX($B$2:$B$502, MATCH(R9, $A$2:$A$502, 0)), "") | N9: 採用 | O9: =IF(N9="採用",1,IF(N9="限定",2,IF(N9="削除",0,""))) -> 1 | P9: =IF(N9="削除",0,1) -> 1 | Q9: 46198 | T9: 05.テトラサイクリン系 | V9: =COUNTIF(R:R,"DR0250") -> 1
A10: DR0009 | B10: レボフロキサシン錠500mg「DSPE」 | C10: レボフロキサシン水和物 | D10: 1日1回1錠 | E10: 内服薬 | F10: 〇 | G10: 〇 | I10: 1.抗菌抗薬 | J10: レボフロキサシンジョウ500ｍｇＤＥＳＰ | K10: 後発 | L10: =IFERROR(_xlfn.TEXTJOIN(" / ",TRUE, IF($R$2:$R$503=A10,$B$2:$B$503,"") ),"") | M10: =IFERROR(INDEX($B$2:$B$502, MATCH(R10, $A$2:$A$502, 0)), "") | N10: 採用 | O10: =IF(N10="採用",1,IF(N10="限定",2,IF(N10="削除",0,""))) -> 1 | P10: =IF(N10="削除",0,1) -> 1 | Q10: 46198 | T10: 06.ニューキノロン系 | V10: =COUNTIF(R:R,"DR0250") -> 1 | W10: 【投与注意】酸化マグネシウム、鉄剤とは1～2時間あける
A11: DR0010 | B11: セフォセフ静注用1g | C11: スルバクタムナトリウム/セフォペラゾンナトリウム | D11: 1日1～2g、2回分割。静注または点滴静注。重症は1日4gまで。 | E11: 注射剤 | I11: 1.抗菌抗薬 | J11: セフォセフジョウチュウヨウ1g | K11: 後発 | L11: =IFERROR(_xlfn.TEXTJOIN(" / ",TRUE, IF($R$2:$R$503=A11,$B$2:$B$503,"") ),"") | M11: =IFERROR(INDEX($B$2:$B$502, MATCH(R11, $A$2:$A$502, 0)), "") | N11: 採用 | O11: =IF(N11="採用",1,IF(N11="限定",2,IF(N11="削除",0,""))) -> 1 | P11: =IF(N11="削除",0,1) -> 1 | Q11: 46198 | T11: 07.βラクタマーゼ阻害 | V11: =COUNTIF(R:R,"DR0250") -> 1
A12: DR0011 | B12: スルバシリン静注用1.5g | C12: スルバクタムナトリウム/アンピシリンナトリウム | D12: （肺炎、肺膿瘍、腹膜炎）1回3g、1日4回まで。（膀胱炎）1回1.5g、1日2回静注、点滴静注 | E12: 注射剤 | I12: 1.抗菌抗薬 | J12: スルバシリンジョウチュウヨウ1.5mg | K12: 後発 | L12: =IFERROR(_xlfn.TEXTJOIN(" / ",TRUE, IF($R$2:$R$503=A12,$B$2:$B$503,"") ),"") | M12: =IFERROR(INDEX($B$2:$B$502, MATCH(R12, $A$2:$A$502, 0)), "") | N12: 採用 | O12: =IF(N12="採用",1,IF(N12="限定",2,IF(N12="削除",0,""))) -> 1 | P12: =IF(N12="削除",0,1) -> 1 | Q12: 46265 | T12: 07.βラクタマーゼ阻害 | V12: =COUNTIF(R:R,"DR0250") -> 1
A13: DR0012 | B13: セフタジジム静注用１g「VTRS」 | C13: セフタジジム水和物 | D13: 1日1～2g、2回分割。静注又は点滴静注。重症：1日4g、2回分割 | E13: 注射剤 | I13: 1.抗菌抗薬 | J13: セフタジジムジョウチュウヨウVTRS | K13: 後発 | L13: =IFERROR(_xlfn.TEXTJOIN(" / ",TRUE, IF($R$2:$R$503=A13,$B$2:$B$503,"") ),"") | M13: =IFERROR(INDEX($B$2:$B$502, MATCH(R13, $A$2:$A$502, 0)), "") | N13: 採用 | O13: =IF(N13="採用",1,IF(N13="限定",2,IF(N13="削除",0,""))) -> 1 | P13: =IF(N13="削除",0,1) -> 1 | Q13: 46198 | T13: 02.セフェム系 | U13: 01.第３世代 | V13: =COUNTIF(R:R,"DR0250") -> 1
A14: DR0013 | B14: セフトリアキソンナトリウム静注用1g「NP」 | C14: セフトリアキソンナトリウム水和物 | D14: 1日1～2g、1～2回分割静注または点滴静注。重症：1日4g、2回分割 | E14: 注射剤 | I14: 1.抗菌抗薬 | J14: セフトリアキソンナトリウムジョウチュウヨウ1gNP | K14: 後発 | L14: =IFERROR(_xlfn.TEXTJOIN(" / ",TRUE, IF($R$2:$R$503=A14,$B$2:$B$503,"") ),"") | M14: =IFERROR(INDEX($B$2:$B$502, MATCH(R14, $A$2:$A$502, 0)), "") | N14: 採用 | O14: =IF(N14="採用",1,IF(N14="限定",2,IF(N14="削除",0,""))) -> 1 | P14: =IF(N14="削除",0,1) -> 1 | Q14: 46198 | T14: 02.セフェム系 | U14: 01.第３世代 | V14: =COUNTIF(R:R,"DR0250") -> 1
A15: DR0014 | B15: メロペネム静注用0.25g「NP」 | C15: メロペネム | D15: 投与期間3日間を目安として継続するか検討。1日0.5g～1gを2～3回に分けて30分以上かけて点滴静注 | E15: 注射剤 | I15: 1.抗菌抗薬 | J15: メロペネムジョウチュウヨウ0.25gNP | K15: 後発 | L15: =IFERROR(_xlfn.TEXTJOIN(" / ",TRUE, IF($R$2:$R$503=A15,$B$2:$B$503,"") ),"") | M15: =IFERROR(INDEX($B$2:$B$502, MATCH(R15, $A$2:$A$502, 0)), "") | N15: 採用 | O15: =IF(N15="採用",1,IF(N15="限定",2,IF(N15="削除",0,""))) -> 1 | P15: =IF(N15="削除",0,1) -> 1 | Q15: 46198 | T15: 08.カルバペネム系 | V15: =COUNTIF(R:R,"DR0250") -> 1
A16: DR0015 | B16: バンコマイシン塩酸塩点滴静注用0.5g「明治」 | C16: バンコマイシン塩酸塩 | D16: 1日2g、1回5g、6時間毎又は、1回1g、12時間毎。60分以上かけて点滴静注。高齢者：1回0.5g、12時間毎又は1回1g、24時間毎。 | E16: 注射剤 | I16: 1.抗菌抗薬 | J16: バンコマイシンエンサンエンテンテキジョウチュウヨウ0.5g | K16: 後発 | L16: =IFERROR(_xlfn.TEXTJOIN(" / ",TRUE, IF($R$2:$R$503=A16,$B$2:$B$503,"") ),"") | M16: =IFERROR(INDEX($B$2:$B$502, MATCH(R16, $A$2:$A$502, 0)), "") | N16: 採用 | O16: =IF(N16="採用",1,IF(N16="限定",2,IF(N16="削除",0,""))) -> 1 | P16: =IF(N16="削除",0,1) -> 1 | Q16: 46198 | T16: 11.グリコペプチド系 | V16: =COUNTIF(R:R,"DR0250") -> 1
A17: DR0016 | B17: ミノサイクリン塩酸塩点滴静注用100mg「サワイ」 | C17: ミノサイクリン塩酸塩 | D17: 初回100～200mg、以降12あるいは24時間毎に100mg点滴静注 | E17: 注射剤 | I17: 1.抗菌抗薬 | J17: ミノサイクリンエンサンエンテンテキジョウチュウヨウ100mgサワイ | K17: 後発 | L17: =IFERROR(_xlfn.TEXTJOIN(" / ",TRUE, IF($R$2:$R$503=A17,$B$2:$B$503,"") ),"") | M17: =IFERROR(INDEX($B$2:$B$502, MATCH(R17, $A$2:$A$502, 0)), "") | N17: 採用 | O17: =IF(N17="採用",1,IF(N17="限定",2,IF(N17="削除",0,""))) -> 1 | P17: =IF(N17="削除",0,1) -> 1 | Q17: 46198 | T17: 05.テトラサイクリン系 | V17: =COUNTIF(R:R,"DR0250") -> 1
A18: DR0017 | B18: タゾピペ配合点滴静注用バック4.5「DESP」 | C18: タゾバクタム/ピペラシン | D18: 1回4.5gを1日3回点滴静注 | E18: 注射剤 | I18: 1.抗菌抗薬 | J18: タゾピペハイゴウテンテキジョウチュウヨウバック4.5DESP | K18: 後発 | L18: =IFERROR(_xlfn.TEXTJOIN(" / ",TRUE, IF($R$2:$R$503=A18,$B$2:$B$503,"") ),"") | M18: =IFERROR(INDEX($B$2:$B$502, MATCH(R18, $A$2:$A$502, 0)), "") | N18: 限定 | O18: =IF(N18="採用",1,IF(N18="限定",2,IF(N18="削除",0,""))) -> 2 | P18: =IF(N18="削除",0,1) -> 1 | Q18: 46198 | S18: 患者限定 | T18: 07.βラクタマーゼ阻害 | V18: =COUNTIF(R:R,"DR0250") -> 1 | W18: 【薬剤科連絡】限定のため使用時に薬剤科へ確認
A19: DR0018 | B19: バクタ配合錠 | C19: スルファメトキサゾール/トリメトプリム | D19: 1日4錠、2回分服（ニューモシスチス肺炎の治療）1日9～12錠、3～4回分服、（発症抑制）1日1～2錠連日又は週3回。 | E19: 内服薬 | F19: 〇 | G19: 〇 | I19: 1.抗菌抗薬 | J19: バクタハイゴウジョウ | K19: 先発 | L19: =IFERROR(_xlfn.TEXTJOIN(" / ",TRUE, IF($R$2:$R$503=A19,$B$2:$B$503,"") ),"") | M19: =IFERROR(INDEX($B$2:$B$502, MATCH(R19, $A$2:$A$502, 0)), "") | N19: 採用 | O19: =IF(N19="採用",1,IF(N19="限定",2,IF(N19="削除",0,""))) -> 1 | P19: =IF(N19="削除",0,1) -> 1 | Q19: 46198 | T19: 12.配合剤 | V19: =COUNTIF(R:R,"DR0250") -> 1
A20: DR0019 | B20: ファロム錠200ｍｇ | C20: ファロペネムナトリウム水和物 | D20: 1回200～300mg、1日3回 | E20: 内服薬 | F20: 〇 | G20: 〇 | I20: 1.抗菌抗薬 | J20: ファロムジョウ200mg | K20: 先発 | L20: =IFERROR(_xlfn.TEXTJOIN(" / ",TRUE, IF($R$2:$R$503=A20,$B$2:$B$503,"") ),"") | M20: =IFERROR(INDEX($B$2:$B$502, MATCH(R20, $A$2:$A$502, 0)), "") | N20: 限定 | O20: =IF(N20="採用",1,IF(N20="限定",2,IF(N20="削除",0,""))) -> 2 | P20: =IF(N20="削除",0,1) -> 1 | Q20: 46198 | S20: 患者限定 | T20: 09.経口ぺネム系 | V20: =COUNTIF(R:R,"DR0250") -> 1 | W20: 【薬剤科連絡】限定採用のため使用時薬剤科へ連絡
A21: DR0020 | B21: ラスビック錠75mg | C21: ラスクフロキサシン塩酸塩 | D21: 1日1回75mg | E21: 内服薬 | F21: △ | G21: 〇 | I21: 1.抗菌抗薬 | J21: ラスビックジョウ75mg | K21: 先発 | L21: =IFERROR(_xlfn.TEXTJOIN(" / ",TRUE, IF($R$2:$R$503=A21,$B$2:$B$503,"") ),"") | M21: =IFERROR(INDEX($B$2:$B$502, MATCH(R21, $A$2:$A$502, 0)), "") | N21: 採用 | O21: =IF(N21="採用",1,IF(N21="限定",2,IF(N21="削除",0,""))) -> 1 | P21: =IF(N21="削除",0,1) -> 1 | Q21: 46198 | T21: 06.ニューキノロン系 | V21: =COUNTIF(R:R,"DR0250") -> 1 | W21: 【調剤注意】粉砕後簡易懸濁
A22: DR0021 | B22: ラスビック点滴静注キット150mg | C22: ラスクフロキサシン塩酸塩 | D22: 初日1日1回300mg、2日目以降1日1回150mg点滴静注 | E22: 注射剤 | I22: 1.抗菌抗薬 | J22: ラスビックテンテキジョウチュウキット150mg | K22: 先発 | L22: =IFERROR(_xlfn.TEXTJOIN(" / ",TRUE, IF($R$2:$R$503=A22,$B$2:$B$503,"") ),"") | M22: =IFERROR(INDEX($B$2:$B$502, MATCH(R22, $A$2:$A$502, 0)), "") | N22: 限定 | O22: =IF(N22="採用",1,IF(N22="限定",2,IF(N22="削除",0,""))) -> 2 | P22: =IF(N22="削除",0,1) -> 1 | Q22: 46260 | S22: 初回分のみ常時在庫 | T22: 06.ニューキノロン系 | V22: =COUNTIF(R:R,"DR0250") -> 1 | W22: 【薬剤科連絡】初回分在庫してるので使用時薬剤科へ連絡
A23: DR0022 | B23: ゲンタマイシン硫酸塩軟膏0.1％「F」 | C23: ゲンタマイシン硫酸塩 | D23: 1日1～数回塗布又はガーゼにて貼付 | E23: 外用薬 | I23: 1.抗菌抗薬 | J23: ゲンタマイシンリュウサンエンナンコウ0.1％F | K23: 後発 | L23: =IFERROR(_xlfn.TEXTJOIN(" / ",TRUE, IF($R$2:$R$503=A23,$B$2:$B$503,"") ),"") | M23: =IFERROR(INDEX($B$2:$B$502, MATCH(R23, $A$2:$A$502, 0)), "") | N23: 採用 | O23: =IF(N23="採用",1,IF(N23="限定",2,IF(N23="削除",0,""))) -> 1 | P23: =IF(N23="削除",0,1) -> 1 | Q23: 46198 | T23: 03.アミノグリコシド系 | V23: =COUNTIF(R:R,"DR0250") -> 1
A24: DR0023 | B24: バラマイシン軟膏 | C24: バラシトラシン/フラジオマイシン硫酸塩 | D24: 1日1～数回塗布 | E24: 外用薬 | I24: 1.抗菌抗薬 | J24: バラマイシンナンコウ | K24: 後発 | L24: =IFERROR(_xlfn.TEXTJOIN(" / ",TRUE, IF($R$2:$R$503=A24,$B$2:$B$503,"") ),"") | M24: =IFERROR(INDEX($B$2:$B$502, MATCH(R24, $A$2:$A$502, 0)), "") | N24: 採用 | O24: =IF(N24="採用",1,IF(N24="限定",2,IF(N24="削除",0,""))) -> 1 | P24: =IF(N24="削除",0,1) -> 1 | Q24: 46198 | T24: 02.ポリペプチド系 | V24: =COUNTIF(R:R,"DR0250") -> 1
A25: DR0024 | B25: ゼビアックスローション２％ | C25: オゼノキサシン | D25: 1日1回 | E25: 外用薬 | I25: 55.皮膚科用剤 | J25: ゼビアックスローション | K25: 先発 | L25: =IFERROR(_xlfn.TEXTJOIN(" / ",TRUE, IF($R$2:$R$503=A25,$B$2:$B$503,"") ),"") | M25: =IFERROR(INDEX($B$2:$B$502, MATCH(R25, $A$2:$A$502, 0)), "") | N25: 採用 | O25: =IF(N25="採用",1,IF(N25="限定",2,IF(N25="削除",0,""))) -> 1 | P25: =IF(N25="削除",0,1) -> 1 | Q25: 46198 | T25: 05.痤創治療薬 | V25: =COUNTIF(R:R,"DR0250") -> 1
A26: DR0025 | B26: オセルタミビルカプセル75ｍｇ「サワイ」 | C26: オセルタミビルリン酸塩 | D26: （治療）1回1ｶﾌﾟｾﾙ、1日2回5日間（予防）1日1回、1回1カプセル7～10日間 | E26: 内服薬 | F26: 〇 | H26: 〇 | I26: 2.抗ウィルス薬 | J26: オセルタミビルカプセル75mgサワイ | K26: 後発 | L26: =IFERROR(_xlfn.TEXTJOIN(" / ",TRUE, IF($R$2:$R$503=A26,$B$2:$B$503,"") ),"") | M26: =IFERROR(INDEX($B$2:$B$502, MATCH(R26, $A$2:$A$502, 0)), "") | N26: 採用 | O26: =IF(N26="採用",1,IF(N26="限定",2,IF(N26="削除",0,""))) -> 1 | P26: =IF(N26="削除",0,1) -> 1 | Q26: 46199 | T26: 01.インフルエンザ | V26: =COUNTIF(R:R,"DR0250") -> 1
A27: DR0026 | B27: ゾフルーザ錠20mg | C27: バロキサビルマルボキシル | D27: （治療及び予防）（80㎏未満）1回2錠（80㎏以上）1回4錠 | E27: 内服薬 | F27: 〇 | G27: △ | I27: 2.抗ウィルス薬 | J27: ゾフルーザジョウ20mg | K27: 先発 | L27: =IFERROR(_xlfn.TEXTJOIN(" / ",TRUE, IF($R$2:$R$503=A27,$B$2:$B$503,"") ),"") | M27: =IFERROR(INDEX($B$2:$B$502, MATCH(R27, $A$2:$A$502, 0)), "") | N27: 採用 | O27: =IF(N27="採用",1,IF(N27="限定",2,IF(N27="削除",0,""))) -> 1 | P27: =IF(N27="削除",0,1) -> 1 | Q27: 46260 | T27: 01.インフルエンザ | V27: =COUNTIF(R:R,"DR0250") -> 1 | W27: 【調剤注意】粉砕時苦味あり
A28: DR0027 | B28: バラシクロビル錠500mg「YD」 | C28: バラシクロビル塩酸塩 | D28: （単純疱疹）1回1錠、1日2回（帯状疱疹・水痘）1回2錠、1日3回 | E28: 内服薬 | F28: △ | G28: △ | I28: 2.抗ウィルス薬 | J28: バラシクロビルジョウ500mgYD | K28: 後発 | L28: =IFERROR(_xlfn.TEXTJOIN(" / ",TRUE, IF($R$2:$R$503=A28,$B$2:$B$503,"") ),"") | M28: =IFERROR(INDEX($B$2:$B$502, MATCH(R28, $A$2:$A$502, 0)), "") | N28: 採用 | O28: =IF(N28="採用",1,IF(N28="限定",2,IF(N28="削除",0,""))) -> 1 | P28: =IF(N28="削除",0,1) -> 1 | Q28: 46199 | T28: 02.帯状疱疹 | V28: =COUNTIF(R:R,"DR0250") -> 1 | W28: 【調剤注意】粉砕後簡易懸濁可。
A29: DR0028 | B29: ラゲブリオ錠400mg | C29: モルヌピラビル | D29: 1回800mg、1日2回5日間 | E29: 内服薬 | F29: 〇 | G29: 〇 | I29: 2.抗ウィルス薬 | J29: ラゲブリオジョウ400mg | K29: 先発 | L29: =IFERROR(_xlfn.TEXTJOIN(" / ",TRUE, IF($R$2:$R$503=A29,$B$2:$B$503,"") ),"") | M29: =IFERROR(INDEX($B$2:$B$502, MATCH(R29, $A$2:$A$502, 0)), "") | N29: 採用 | O29: =IF(N29="採用",1,IF(N29="限定",2,IF(N29="削除",0,""))) -> 1 | P29: =IF(N29="削除",0,1) -> 1 | Q29: 46199 | T29: 03.新型コロナウィルス | V29: =COUNTIF(R:R,"DR0250") -> 1
A30: DR0029 | B30: ビダラビン軟膏3％「SW」 | C30: ビダラビン | D30: 1日1～４回塗布または貼付 | E30: 外用薬 | I30: 2.抗ウィルス薬 | J30: ビダラビンナンコウ３％ | K30: 後発 | L30: =IFERROR(_xlfn.TEXTJOIN(" / ",TRUE, IF($R$2:$R$503=A30,$B$2:$B$503,"") ),"") | M30: =IFERROR(INDEX($B$2:$B$502, MATCH(R30, $A$2:$A$502, 0)), "") | N30: 採用 | O30: =IF(N30="採用",1,IF(N30="限定",2,IF(N30="削除",0,""))) -> 1 | P30: =IF(N30="削除",0,1) -> 1 | Q30: 46199 | T30: 02.帯状疱疹 | V30: =COUNTIF(R:R,"DR0250") -> 1
A31: DR0030 | B31: イナビル吸入粉末剤20mg | C31: ラニナミビルオクタン酸エステル | D31: ※ | E31: 外用薬 | I31: 2.抗ウィルス薬 | J31: イナビルキュウニュウフンマツザイ20mg | K31: 先発 | L31: =IFERROR(_xlfn.TEXTJOIN(" / ",TRUE, IF($R$2:$R$503=A31,$B$2:$B$503,"") ),"") | M31: =IFERROR(INDEX($B$2:$B$502, MATCH(R31, $A$2:$A$502, 0)), "") | N31: 採用 | O31: =IF(N31="採用",1,IF(N31="限定",2,IF(N31="削除",0,""))) -> 1 | P31: =IF(N31="削除",0,1) -> 1 | Q31: 46199 | T31: 01.インフルエンザ | V31: =COUNTIF(R:R,"DR0250") -> 1 | W31: 【その他】用法用量について今日の治療薬参照または薬剤科へ
A32: DR0031 | B32: ラピアクタ点滴静注液バッグ300mg | C32: ベラミビル水和物 | D32: 300mgを15分以上かけて単回点滴静注。重症化の恐れのとき：1日1回600mg、症状に応じて連日反復投与可 | E32: 注射剤 | I32: 2.抗ウィルス薬 | J32: ラピアクタテンテキジョウチュウエキバッグ300mg | K32: 先発 | L32: =IFERROR(_xlfn.TEXTJOIN(" / ",TRUE, IF($R$2:$R$503=A32,$B$2:$B$503,"") ),"") | M32: =IFERROR(INDEX($B$2:$B$502, MATCH(R32, $A$2:$A$502, 0)), "") | N32: 採用 | O32: =IF(N32="採用",1,IF(N32="限定",2,IF(N32="削除",0,""))) -> 1 | P32: =IF(N32="削除",0,1) -> 1 | Q32: 46199 | T32: 01.インフルエンザ | V32: =COUNTIF(R:R,"DR0250") -> 1
A33: DR0032 | B33: アシクロビル点滴静注液250mg「日医工」 | C33: アシクロビル | D33: 1回5mg/kg、1日3回、8時間毎に1時間以上かけて7日間。 | E33: 注射剤 | I33: 2.抗ウィルス薬 | J33: アシクロビルテンテキジョウチュウエキ250mgニチイコウ | K33: 後発 | L33: =IFERROR(_xlfn.TEXTJOIN(" / ",TRUE, IF($R$2:$R$503=A33,$B$2:$B$503,"") ),"") | M33: =IFERROR(INDEX($B$2:$B$502, MATCH(R33, $A$2:$A$502, 0)), "") | N33: 採用 | O33: =IF(N33="採用",1,IF(N33="限定",2,IF(N33="削除",0,""))) -> 1 | P33: =IF(N33="削除",0,1) -> 1 | Q33: 46199 | T33: 02.帯状疱疹 | V33: =COUNTIF(R:R,"DR0250") -> 1
A34: DR0033 | B34: ベクルリー点滴静注用100mg | C34: レムデシビル | D34: 1日1回点滴静注。初日200mg、2日目以降100mg | E34: 注射剤 | I34: 2.抗ウィルス薬 | J34: ベクルリーテンテキジョウチュウヨウ100mg | K34: 先発 | L34: =IFERROR(_xlfn.TEXTJOIN(" / ",TRUE, IF($R$2:$R$503=A34,$B$2:$B$503,"") ),"") | M34: =IFERROR(INDEX($B$2:$B$502, MATCH(R34, $A$2:$A$502, 0)), "") | N34: 採用 | O34: =IF(N34="採用",1,IF(N34="限定",2,IF(N34="削除",0,""))) -> 1 | P34: =IF(N34="削除",0,1) -> 1 | Q34: 46199 | T34: 03.新型コロナウィルス | V34: =COUNTIF(R:R,"DR0250") -> 1
A35: DR0034 | B35: ハリゾンシロップ100mg/ｍL | C35: アムホテリシンB | D35: 1回50～100ｍｇ、1日2～4回 | E35: 内服薬 | I35: 3.抗真菌薬 | J35: ハリゾンシロップ100mg/ｍL | K35: 後発 | L35: =IFERROR(_xlfn.TEXTJOIN(" / ",TRUE, IF($R$2:$R$503=A35,$B$2:$B$503,"") ),"") | M35: =IFERROR(INDEX($B$2:$B$502, MATCH(R35, $A$2:$A$502, 0)), "") | N35: 削除 | O35: =IF(N35="採用",1,IF(N35="限定",2,IF(N35="削除",0,""))) -> 0 | P35: =IF(N35="削除",0,1) -> 0 | Q35: 46199 | V35: =COUNTIF(R:R,"DR0250") -> 1
A36: DR0035 | B36: フルコナゾールカプセル100ｍｇ「サワイ」 | C36: フルコナゾール | D36: ※ | E36: 内服薬 | F36: 〇 | H36: 〇 | I36: 3.抗真菌薬 | J36: フルコナゾールカプセル100mgサワイ | K36: 後発 | L36: =IFERROR(_xlfn.TEXTJOIN(" / ",TRUE, IF($R$2:$R$503=A36,$B$2:$B$503,"") ),"") | M36: =IFERROR(INDEX($B$2:$B$502, MATCH(R36, $A$2:$A$502, 0)), "") | N36: 採用 | O36: =IF(N36="採用",1,IF(N36="限定",2,IF(N36="削除",0,""))) -> 1 | P36: =IF(N36="削除",0,1) -> 1 | Q36: 46199 | V36: =COUNTIF(R:R,"DR0250") -> 1 | W36: 【その他】用法用量について今日の治療薬参照または薬剤科へ
A37: DR0036 | B37: アスタット液1％ | C37: ラノコナゾール | D37: 1日1回 | E37: 外用薬 | I37: 3.抗真菌薬 | J37: アスタットエキ１％ | K37: 先発 | L37: =IFERROR(_xlfn.TEXTJOIN(" / ",TRUE, IF($R$2:$R$503=A37,$B$2:$B$503,"") ),"") | M37: =IFERROR(INDEX($B$2:$B$502, MATCH(R37, $A$2:$A$502, 0)), "") | N37: 採用 | O37: =IF(N37="採用",1,IF(N37="限定",2,IF(N37="削除",0,""))) -> 1 | P37: =IF(N37="削除",0,1) -> 1 | Q37: 46199 | V37: =COUNTIF(R:R,"DR0250") -> 1
A38: DR0037 | B38: アスタットクリーム1％ | C38: ラノコナゾール | D38: 1日1回 | E38: 外用薬 | I38: 3.抗真菌薬 | J38: アスタットクリーム1% | K38: 先発 | L38: =IFERROR(_xlfn.TEXTJOIN(" / ",TRUE, IF($R$2:$R$503=A38,$B$2:$B$503,"") ),"") | M38: =IFERROR(INDEX($B$2:$B$502, MATCH(R38, $A$2:$A$502, 0)), "") | N38: 採用 | O38: =IF(N38="採用",1,IF(N38="限定",2,IF(N38="削除",0,""))) -> 1 | P38: =IF(N38="削除",0,1) -> 1 | Q38: 46199 | V38: =COUNTIF(R:R,"DR0250") -> 1
A39: DR0038 | B39: ルリコナゾールクリーム1%「イワキ」 | C39: ルリコナゾール | D39: 1日1回 | E39: 外用薬 | I39: 3.抗真菌薬 | J39: ルリコナゾールクリーム1%イワキ | K39: 後発 | L39: =IFERROR(_xlfn.TEXTJOIN(" / ",TRUE, IF($R$2:$R$503=A39,$B$2:$B$503,"") ),"") | M39: =IFERROR(INDEX($B$2:$B$502, MATCH(R39, $A$2:$A$502, 0)), "") | N39: 採用 | O39: =IF(N39="採用",1,IF(N39="限定",2,IF(N39="削除",0,""))) -> 1 | P39: =IF(N39="削除",0,1) -> 1 | Q39: 46199 | V39: =COUNTIF(R:R,"DR0250") -> 1
A40: DR0039 | B40: ビホナゾールクリーム1%「YD」 | C40: ビホナゾール | D40: 1日1回 | E40: 外用薬 | I40: 3.抗真菌薬 | J40: ビホナゾールクリーム1%ヨウジンドウ | K40: 後発 | L40: =IFERROR(_xlfn.TEXTJOIN(" / ",TRUE, IF($R$2:$R$503=A40,$B$2:$B$503,"") ),"") | M40: =IFERROR(INDEX($B$2:$B$502, MATCH(R40, $A$2:$A$502, 0)), "") | N40: 採用 | O40: =IF(N40="採用",1,IF(N40="限定",2,IF(N40="削除",0,""))) -> 1 | P40: =IF(N40="削除",0,1) -> 1 | Q40: 46199 | V40: =COUNTIF(R:R,"DR0250") -> 1
...

Sheet 改訂履歴
A1: 改訂No. | B1: 改訂日 | C1: 変更区分 | D1: 薬品ID | E1: 薬品名 | F1: 変更前 | G1: 変更後 | H1: 変更理由 | I1: 担当者 | J1: 確認者 | K1: 備考
A2: 1 | B2: 46241 | C2: 変更 | D2: DR388 | E2: 酸化マグネシウム錠500mg「ヨシダ」 | F2: 採用 | G2: 削除 | H2: メーカー変更 | I2: 薬局長 | J2: 薬局長
B3: 46241 | C3: 変更 | D3: DR0599 | E3: 酸化マグネシウム錠500mg「ケンエー」 | G3: 採用 | H3: メーカー変更 | I3: 薬局長 | J3: 薬局長 | K3: メーカー変更のため新規追加
A4: 2 | B4: 46241 | C4: 変更 | D4: DR0070 | E4: アセトアミノフェン錠200mg「マルイシ」 | F4: 採用 | G4: 削除 | H4: メーカー変更 | I4: 薬局長 | J4: 薬局長
B5: 46241 | C5: 変更 | D5: DR0600 | E5: アセトアミノフェン錠200mg「ケンエー」 | G5: 採用 | H5: メーカー変更 | I5: 薬局長 | J5: 薬局長 | K5: メーカー変更のため新規追加
A6: 3 | B6: 46248 | C6: 新規採用 | D6: DR0601 | E6: L-アスパラギン酸K「NIG」 | G6: 追加 | H6: 新規採用 | I6: 薬局長 | J6: 薬局長 | K6: 入力忘れのため追加
A7: 4 | B7: 46248 | C7: 新規採用 | D7: DR0602 | E7: KCL補正液 | G7: 採用 | H7: 新規採用 | I7: 薬局長 | J7: 薬局長 | K7: 患者限定採用
A8: 5 | B8: 46259 | C8: 訂正 | D8: DR0221 | E8: ハイカリックRF | F8: ハイカリッフ | G8: ハイカリック | H8: 入力修正 | I8: 薬局長 | J8: 薬局長 | K8: 薬品名修正
A9: 6 | B9: 46260 | C9: 訂正 | D9: DR0020 | E9: ラスビック点滴静注 | H9: 入力修正 | I9: 薬局長 | J9: 薬局長 | K9: 備考欄修正
A10: 7 | B10: 46258 | D10: 該当の薬品 | H10: 情報更新 | I10: 薬局長 | J10: 薬局長 | K10: 薬剤科コメント列追加、該当の薬品にコメント追加
A11: 8 | B11: 46260 | C11: 訂正 | D11: DR0026 | E11: ゾフルーザ錠20mg | H11: 入力修正 | I11: 薬局長 | J11: 薬局長 | K11: 簡易懸濁可、粉砕条件付き可へ変更
A12: 9 | B12: 46260 | C12: 訂正 | D12: DR0027 | E12: バラシクロビル錠500mg「YD」 | F12: 簡易懸濁✖ | G12: 簡易懸濁△ | H12: 入力修正 | I12: 薬局長 | J12: 薬局長 | K12: 簡易懸濁条件付き可へ変更
A13: 10 | B13: 46261 | C13: 新規採用 | D13: DR0603 | E13: アタラックス-P注射液 | G13: 追加 | H13: 新規採用 | I13: 薬局長 | J13: 薬局長 | K13: 入れ忘れのため追加
A14: 11 | B14: 46261 | C14: 訂正 | D14: DR0042 | E14: クロマイ膣錠 | F14: 01クロラムフェニコール系 | G14: 13クロラムフェニコール系 | H14: 入力修正 | I14: 薬局長 | J14: 薬局長 | K14: 薬効分類（中）を修正
A15: 12 | B15: 46265 | C15: 訂正 | D15: DR0010 | E15: スルバシリン | F15: スリバシリン | G15: スルバシリン | H15: 入力修正 | I15: 薬局長 | J15: 薬局長 | K15: 薬品名修正
A16: 13 | B16: 46267 | C16: 新規採用 | D16: DR0604 | E16: メトジェクト皮下7.5mgシリンジ0.15ｍL | H16: 新規採用 | I16: 薬局長 | J16: 薬局長 | K16: 外来へ払い出してるので新規追加
A17: 14 | B17: 46267 | C17: 新規採用 | D17: DR0605 | E17: ダルベポエチンアルファBS注60㎍シリンジ「三和」 | H17: 新規採用 | I17: 薬局長 | J17: 薬局長
B18: 46267 | C18: 新規採用 | D18: DR0606 | E18: ダルベポエチンアルファBS注120㎍シリンジ「三和」 | H18: 新規採用 | I18: 薬局長 | J18: 薬局長
A19: 15 | B19: 46269 | C19: 採用中止 | D19: DR0079 | E19: ジクロフェナクNaテープ30mg日本臓器 | H19: 販売中止 | I19: 薬局長 | J19: 薬局長
B20: 46269 | C20: 新規採用 | D20: DR0607 | E20: ジクロフェナクNaテープ30ｍｇ「ユートク」 | H20: 新規採用 | I20: 薬局長 | J20: 薬局長 | K20: メーカー変更のため新規追加

Sheet 印刷用
A1: 薬品ID | B1: 薬品名 | C1: 成分名 | D1: 用法用量 | E1: 区分 | F1: 簡易懸濁可否 | G1: 粉砕可否 | H1: 脱カプセル可否 | I1: 薬効分類（大） | J1: 薬効分類（中） | K1: 薬効分類（小） | L1: 薬品カナ | M1: 先発名 | N1: 後発名 | O1: 採用区分 | P1: 備考欄 | Q1: 分類見出し | R1: 分類見出し表示 | S1: 薬品名表示 | T1: 薬品詳細表示
A2: {=IFERROR(INDEX(薬品マスタ!$A$2:$A$999, SMALL(IF(薬品マスタ!$P$2:$P$999=1, ROW(薬品マスタ!$A$2:$A$999)-ROW(薬品マスタ!$A$2)+1), ROW(A1))),"")} -> DR0001 | B2: =IF($A2="","",INDEX(薬品マスタ!$B$2:$B$999,MATCH($A2,薬品マスタ!$A$2:$A$999,0))) -> ユナシン錠375ｍｇ | C2: =IF($A2="","",INDEX(薬品マスタ!$C$2:$C$999,MATCH($A2,薬品マスタ!$A$2:$A$999,0))) -> スルタミシリントシル酸塩水和物 | D2: =IF($A2="","",INDEX(薬品マスタ!$D$2:$D$999,MATCH($A2,薬品マスタ!$A$2:$A$999,0))) -> 1回1錠1日2～3回 | E2: =IF($A2="","",INDEX(薬品マスタ!$E$2:$E$999,MATCH($A2,薬品マスタ!$A$2:$A$999,0))) -> 内服薬 | F2: =IF($A2="","",INDEX(薬品マスタ!$F$2:$F$999,MATCH($A2,薬品マスタ!$A$2:$A$999,0))&"") -> 〇 | G2: =IF($A2="","",INDEX(薬品マスタ!$G$2:$G$999,MATCH($A2,薬品マスタ!$A$2:$A$999,0))&"") -> 〇 | H2: =IF($A2="","",INDEX(薬品マスタ!$H$2:$H$999,MATCH($A2,薬品マスタ!$A$2:$A$999,0))&"") | I2: =IF($A2="","",INDEX(薬品マスタ!$I$2:$I$999,MATCH($A2,薬品マスタ!$A$2:$A$999,0))&"") -> 1.抗菌抗薬 | J2: =IF($A2="","",INDEX(薬品マスタ!$T$2:$T$999,MATCH($A2,薬品マスタ!$A$2:$A$999,0))&"") -> 01.広範囲ペニシリン系 | K2: =IF($A2="","",INDEX(薬品マスタ!$U$2:$U$999,MATCH($A2,薬品マスタ!$A$2:$A$999,0))&"") | L2: =IF($A2="","",INDEX(薬品マスタ!$J$2:$J$999,MATCH($A2,薬品マスタ!$A$2:$A$999,0))&"") -> ユナシンジョウ | M2: =IF($A2="","",INDEX(薬品マスタ!$M$2:$M$999,MATCH($A2,薬品マスタ!$A$2:$A$999,0))&"") | N2: =IF($A2="","",INDEX(薬品マスタ!$L$2:$L$999,MATCH($A2,薬品マスタ!$A$2:$A$999,0))&"") | O2: =IF($A2="","",INDEX(薬品マスタ!$N$2:$N$999,MATCH($A2,薬品マスタ!$A$2:$A$999,0))) -> 採用 | P2: =IF($A2="","",INDEX(薬品マスタ!$S$2:$S$999,MATCH($A2,薬品マスタ!$A$2:$A$999,0))&"") | Q2: ="【"&I2& IF(J2<>"","／"&J2,"")& IF(K2<>"","／"&K2,"")& "】" -> 【 1.抗菌抗薬／01.広範囲ペニシリン系】 | R2: =IF(OR(I2<>I1,J2<>J1,K2<>K1),Q2,"") -> 【 1.抗菌抗薬／01.広範囲ペニシリン系】 | S2: =IF($A2="","","■ "&$B2) -> ■ ユナシン錠375ｍｇ | T2: =IF($A2="","", "成分："&$C2&CHAR(10)& "用法："&$D2&CHAR(10)& $E2& " "&$O2& " 懸濁："&$F2& " 粉砕："&$G2& " 脱カ："&$H2) -> 成分：スルタミシリントシル酸塩水和物 用法：1回1錠1日2～3回 内服薬 採用 懸濁：〇 粉砕：〇 脱カ：
A3: {=IFERROR(INDEX(薬品マスタ!$A$2:$A$999, SMALL(IF(薬品マスタ!$P$2:$P$999=1, ROW(薬品マスタ!$A$2:$A$999)-ROW(薬品マスタ!$A$2)+1), ROW(A2))),"")} -> DR0002 | B3: =IF($A3="","",INDEX(薬品マスタ!$B$2:$B$999,MATCH($A3,薬品マスタ!$A$2:$A$999,0))) -> セフジトレンピボキシル錠100ｍｇ「SW」 | C3: =IF($A3="","",INDEX(薬品マスタ!$C$2:$C$999,MATCH($A3,薬品マスタ!$A$2:$A$999,0))) -> セフジトレンピボキシル | D3: =IF($A3="","",INDEX(薬品マスタ!$D$2:$D$999,MATCH($A3,薬品マスタ!$A$2:$A$999,0))) -> 1回1錠1日3回 | E3: =IF($A3="","",INDEX(薬品マスタ!$E$2:$E$999,MATCH($A3,薬品マスタ!$A$2:$A$999,0))) -> 内服薬 | F3: =IF($A3="","",INDEX(薬品マスタ!$F$2:$F$999,MATCH($A3,薬品マスタ!$A$2:$A$999,0))&"") -> 〇 | G3: =IF($A3="","",INDEX(薬品マスタ!$G$2:$G$999,MATCH($A3,薬品マスタ!$A$2:$A$999,0))&"") -> 〇 | H3: =IF($A3="","",INDEX(薬品マスタ!$H$2:$H$999,MATCH($A3,薬品マスタ!$A$2:$A$999,0))&"") | I3: =IF($A3="","",INDEX(薬品マスタ!$I$2:$I$999,MATCH($A3,薬品マスタ!$A$2:$A$999,0))&"") -> 1.抗菌抗薬 | J3: =IF($A3="","",INDEX(薬品マスタ!$T$2:$T$999,MATCH($A3,薬品マスタ!$A$2:$A$999,0))&"") -> 02.セフェム系 | K3: =IF($A3="","",INDEX(薬品マスタ!$U$2:$U$999,MATCH($A3,薬品マスタ!$A$2:$A$999,0))&"") -> 01.第３世代 | L3: =IF($A3="","",INDEX(薬品マスタ!$J$2:$J$999,MATCH($A3,薬品マスタ!$A$2:$A$999,0))&"") -> セフジトレンピボキシルジョウ100mgサワイ | M3: =IF($A3="","",INDEX(薬品マスタ!$M$2:$M$999,MATCH($A3,薬品マスタ!$A$2:$A$999,0))&"") | N3: =IF($A3="","",INDEX(薬品マスタ!$L$2:$L$999,MATCH($A3,薬品マスタ!$A$2:$A$999,0))&"") | O3: =IF($A3="","",INDEX(薬品マスタ!$N$2:$N$999,MATCH($A3,薬品マスタ!$A$2:$A$999,0))) -> 採用 | P3: =IF($A3="","",INDEX(薬品マスタ!$S$2:$S$999,MATCH($A3,薬品マスタ!$A$2:$A$999,0))&"") | Q3: ="【"&I3& IF(J3<>"","／"&J3,"")& IF(K3<>"","／"&K3,"")& "】" -> 【 1.抗菌抗薬／02.セフェム系／01.第３世代】 | R3: =IF(OR(I3<>I2,J3<>J2,K3<>K2),Q3,"") -> 【 1.抗菌抗薬／02.セフェム系／01.第３世代】 | S3: =IF($A3="","","■ "&$B3) -> ■ セフジトレンピボキシル錠100ｍｇ「SW」 | T3: =IF($A3="","", "成分："&$C3&CHAR(10)& "用法："&$D3&CHAR(10)& $E3& " "&$O3& " 懸濁："&$F3& " 粉砕："&$G3& " 脱カ："&$H3) -> 成分：セフジトレンピボキシル 用法：1回1錠1日3回 内服薬 採用 懸濁：〇 粉砕：〇 脱カ：
A4: {=IFERROR(INDEX(薬品マスタ!$A$2:$A$999, SMALL(IF(薬品マスタ!$P$2:$P$999=1, ROW(薬品マスタ!$A$2:$A$999)-ROW(薬品マスタ!$A$2)+1), ROW(A3))),"")} -> DR0003 | B4: =IF($A4="","",INDEX(薬品マスタ!$B$2:$B$999,MATCH($A4,薬品マスタ!$A$2:$A$999,0))) -> セフカペンピボキシル塩酸塩錠100mg「SW」 | C4: =IF($A4="","",INDEX(薬品マスタ!$C$2:$C$999,MATCH($A4,薬品マスタ!$A$2:$A$999,0))) -> セフカペンピボキシル塩酸塩 | D4: =IF($A4="","",INDEX(薬品マスタ!$D$2:$D$999,MATCH($A4,薬品マスタ!$A$2:$A$999,0))) -> 1回1錠、1日3回。難治性には1回2錠 | E4: =IF($A4="","",INDEX(薬品マスタ!$E$2:$E$999,MATCH($A4,薬品マスタ!$A$2:$A$999,0))) -> 内服薬 | F4: =IF($A4="","",INDEX(薬品マスタ!$F$2:$F$999,MATCH($A4,薬品マスタ!$A$2:$A$999,0))&"") -> 〇 | G4: =IF($A4="","",INDEX(薬品マスタ!$G$2:$G$999,MATCH($A4,薬品マスタ!$A$2:$A$999,0))&"") -> 〇 | H4: =IF($A4="","",INDEX(薬品マスタ!$H$2:$H$999,MATCH($A4,薬品マスタ!$A$2:$A$999,0))&"") | I4: =IF($A4="","",INDEX(薬品マスタ!$I$2:$I$999,MATCH($A4,薬品マスタ!$A$2:$A$999,0))&"") -> 1.抗菌抗薬 | J4: =IF($A4="","",INDEX(薬品マスタ!$T$2:$T$999,MATCH($A4,薬品マスタ!$A$2:$A$999,0))&"") -> 02.セフェム系 | K4: =IF($A4="","",INDEX(薬品マスタ!$U$2:$U$999,MATCH($A4,薬品マスタ!$A$2:$A$999,0))&"") -> 01.第３世代 | L4: =IF($A4="","",INDEX(薬品マスタ!$J$2:$J$999,MATCH($A4,薬品マスタ!$A$2:$A$999,0))&"") -> セフカペンピボキシルエンサンエン100mgサワイ | M4: =IF($A4="","",INDEX(薬品マスタ!$M$2:$M$999,MATCH($A4,薬品マスタ!$A$2:$A$999,0))&"") | N4: =IF($A4="","",INDEX(薬品マスタ!$L$2:$L$999,MATCH($A4,薬品マスタ!$A$2:$A$999,0))&"") | O4: =IF($A4="","",INDEX(薬品マスタ!$N$2:$N$999,MATCH($A4,薬品マスタ!$A$2:$A$999,0))) -> 採用 | P4: =IF($A4="","",INDEX(薬品マスタ!$S$2:$S$999,MATCH($A4,薬品マスタ!$A$2:$A$999,0))&"") | Q4: ="【"&I4& IF(J4<>"","／"&J4,"")& IF(K4<>"","／"&K4,"")& "】" -> 【 1.抗菌抗薬／02.セフェム系／01.第３世代】 | R4: =IF(OR(I4<>I3,J4<>J3,K4<>K3),Q4,"") | S4: =IF($A4="","","■ "&$B4) -> ■ セフカペンピボキシル塩酸塩錠100mg「SW」 | T4: =IF($A4="","", "成分："&$C4&CHAR(10)& "用法："&$D4&CHAR(10)& $E4& " "&$O4& " 懸濁："&$F4& " 粉砕："&$G4& " 脱カ："&$H4) -> 成分：セフカペンピボキシル塩酸塩 用法：1回1錠、1日3回。難治性には1回2錠 内服薬 採用 懸濁：〇 粉砕：〇 脱カ：
A5: {=IFERROR(INDEX(薬品マスタ!$A$2:$A$999, SMALL(IF(薬品マスタ!$P$2:$P$999=1, ROW(薬品マスタ!$A$2:$A$999)-ROW(薬品マスタ!$A$2)+1), ROW(A4))),"")} -> DR0004 | B5: =IF($A5="","",INDEX(薬品マスタ!$B$2:$B$999,MATCH($A5,薬品マスタ!$A$2:$A$999,0))) -> カナマイシンカプセル250mg「明治」 | C5: =IF($A5="","",INDEX(薬品マスタ!$C$2:$C$999,MATCH($A5,薬品マスタ!$A$2:$A$999,0))) -> カナマイシン硫酸塩 | D5: =IF($A5="","",INDEX(薬品マスタ!$D$2:$D$999,MATCH($A5,薬品マスタ!$A$2:$A$999,0))) -> 1日0.5～1g、1日4回 | E5: =IF($A5="","",INDEX(薬品マスタ!$E$2:$E$999,MATCH($A5,薬品マスタ!$A$2:$A$999,0))) -> 内服薬 | F5: =IF($A5="","",INDEX(薬品マスタ!$F$2:$F$999,MATCH($A5,薬品マスタ!$A$2:$A$999,0))&"") -> 〇 | G5: =IF($A5="","",INDEX(薬品マスタ!$G$2:$G$999,MATCH($A5,薬品マスタ!$A$2:$A$999,0))&"") | H5: =IF($A5="","",INDEX(薬品マスタ!$H$2:$H$999,MATCH($A5,薬品マスタ!$A$2:$A$999,0))&"") -> 〇 | I5: =IF($A5="","",INDEX(薬品マスタ!$I$2:$I$999,MATCH($A5,薬品マスタ!$A$2:$A$999,0))&"") -> 1.抗菌抗薬 | J5: =IF($A5="","",INDEX(薬品マスタ!$T$2:$T$999,MATCH($A5,薬品マスタ!$A$2:$A$999,0))&"") -> 03.アミノグリコシド系 | K5: =IF($A5="","",INDEX(薬品マスタ!$U$2:$U$999,MATCH($A5,薬品マスタ!$A$2:$A$999,0))&"") | L5: =IF($A5="","",INDEX(薬品マスタ!$J$2:$J$999,MATCH($A5,薬品マスタ!$A$2:$A$999,0))&"") -> カナマイシンカプセル250mgメイジ | M5: =IF($A5="","",INDEX(薬品マスタ!$M$2:$M$999,MATCH($A5,薬品マスタ!$A$2:$A$999,0))&"") | N5: =IF($A5="","",INDEX(薬品マスタ!$L$2:$L$999,MATCH($A5,薬品マスタ!$A$2:$A$999,0))&"") | O5: =IF($A5="","",INDEX(薬品マスタ!$N$2:$N$999,MATCH($A5,薬品マスタ!$A$2:$A$999,0))) -> 採用 | P5: =IF($A5="","",INDEX(薬品マスタ!$S$2:$S$999,MATCH($A5,薬品マスタ!$A$2:$A$999,0))&"") | Q5: ="【"&I5& IF(J5<>"","／"&J5,"")& IF(K5<>"","／"&K5,"")& "】" -> 【 1.抗菌抗薬／03.アミノグリコシド系】 | R5: =IF(OR(I5<>I4,J5<>J4,K5<>K4),Q5,"") -> 【 1.抗菌抗薬／03.アミノグリコシド系】 | S5: =IF($A5="","","■ "&$B5) -> ■ カナマイシンカプセル250mg「明治」 | T5: =IF($A5="","", "成分："&$C5&CHAR(10)& "用法："&$D5&CHAR(10)& $E5& " "&$O5& " 懸濁："&$F5& " 粉砕："&$G5& " 脱カ："&$H5) -> 成分：カナマイシン硫酸塩 用法：1日0.5～1g、1日4回 内服薬 採用 懸濁：〇 粉砕： 脱カ：〇
A6: {=IFERROR(INDEX(薬品マスタ!$A$2:$A$999, SMALL(IF(薬品マスタ!$P$2:$P$999=1, ROW(薬品マスタ!$A$2:$A$999)-ROW(薬品マスタ!$A$2)+1), ROW(A5))),"")} -> DR0005 | B6: =IF($A6="","",INDEX(薬品マスタ!$B$2:$B$999,MATCH($A6,薬品マスタ!$A$2:$A$999,0))) -> エリスロシンドライシロップW20％ | C6: =IF($A6="","",INDEX(薬品マスタ!$C$2:$C$999,MATCH($A6,薬品マスタ!$A$2:$A$999,0))) -> エリスロマイシンエチルコハク酸エステル | D6: =IF($A6="","",INDEX(薬品マスタ!$D$2:$D$999,MATCH($A6,薬品マスタ!$A$2:$A$999,0))) -> 1回800～1200mg、4～6回 | E6: =IF($A6="","",INDEX(薬品マスタ!$E$2:$E$999,MATCH($A6,薬品マスタ!$A$2:$A$999,0))) -> 内服薬 | F6: =IF($A6="","",INDEX(薬品マスタ!$F$2:$F$999,MATCH($A6,薬品マスタ!$A$2:$A$999,0))&"") -> 〇 | G6: =IF($A6="","",INDEX(薬品マスタ!$G$2:$G$999,MATCH($A6,薬品マスタ!$A$2:$A$999,0))&"") | H6: =IF($A6="","",INDEX(薬品マスタ!$H$2:$H$999,MATCH($A6,薬品マスタ!$A$2:$A$999,0))&"") | I6: =IF($A6="","",INDEX(薬品マスタ!$I$2:$I$999,MATCH($A6,薬品マスタ!$A$2:$A$999,0))&"") -> 1.抗菌抗薬 | J6: =IF($A6="","",INDEX(薬品マスタ!$T$2:$T$999,MATCH($A6,薬品マスタ!$A$2:$A$999,0))&"") -> 04.マクロライド系 | K6: =IF($A6="","",INDEX(薬品マスタ!$U$2:$U$999,MATCH($A6,薬品マスタ!$A$2:$A$999,0))&"") | L6: =IF($A6="","",INDEX(薬品マスタ!$J$2:$J$999,MATCH($A6,薬品マスタ!$A$2:$A$999,0))&"") -> エリスロシンドライシロップW10％ | M6: =IF($A6="","",INDEX(薬品マスタ!$M$2:$M$999,MATCH($A6,薬品マスタ!$A$2:$A$999,0))&"") | N6: =IF($A6="","",INDEX(薬品マスタ!$L$2:$L$999,MATCH($A6,薬品マスタ!$A$2:$A$999,0))&"") | O6: =IF($A6="","",INDEX(薬品マスタ!$N$2:$N$999,MATCH($A6,薬品マスタ!$A$2:$A$999,0))) -> 採用 | P6: =IF($A6="","",INDEX(薬品マスタ!$S$2:$S$999,MATCH($A6,薬品マスタ!$A$2:$A$999,0))&"") | Q6: ="【"&I6& IF(J6<>"","／"&J6,"")& IF(K6<>"","／"&K6,"")& "】" -> 【 1.抗菌抗薬／04.マクロライド系】 | R6: =IF(OR(I6<>I5,J6<>J5,K6<>K5),Q6,"") -> 【 1.抗菌抗薬／04.マクロライド系】 | S6: =IF($A6="","","■ "&$B6) -> ■ エリスロシンドライシロップW20％ | T6: =IF($A6="","", "成分："&$C6&CHAR(10)& "用法："&$D6&CHAR(10)& $E6& " "&$O6& " 懸濁："&$F6& " 粉砕："&$G6& " 脱カ："&$H6) -> 成分：エリスロマイシンエチルコハク酸エステル 用法：1回800～1200mg、4～6回 内服薬 採用 懸濁：〇 粉砕： 脱カ：
A7: {=IFERROR(INDEX(薬品マスタ!$A$2:$A$999, SMALL(IF(薬品マスタ!$P$2:$P$999=1, ROW(薬品マスタ!$A$2:$A$999)-ROW(薬品マスタ!$A$2)+1), ROW(A6))),"")} -> DR0006 | B7: =IF($A7="","",INDEX(薬品マスタ!$B$2:$B$999,MATCH($A7,薬品マスタ!$A$2:$A$999,0))) -> クラリスロマイシン錠200mg「大正」 | C7: =IF($A7="","",INDEX(薬品マスタ!$C$2:$C$999,MATCH($A7,薬品マスタ!$A$2:$A$999,0))) -> クラリスロマイシン | D7: =IF($A7="","",INDEX(薬品マスタ!$D$2:$D$999,MATCH($A7,薬品マスタ!$A$2:$A$999,0))) -> 1回1錠、1日2回 | E7: =IF($A7="","",INDEX(薬品マスタ!$E$2:$E$999,MATCH($A7,薬品マスタ!$A$2:$A$999,0))) -> 内服薬 | F7: =IF($A7="","",INDEX(薬品マスタ!$F$2:$F$999,MATCH($A7,薬品マスタ!$A$2:$A$999,0))&"") -> 〇 | G7: =IF($A7="","",INDEX(薬品マスタ!$G$2:$G$999,MATCH($A7,薬品マスタ!$A$2:$A$999,0))&"") -> 〇 | H7: =IF($A7="","",INDEX(薬品マスタ!$H$2:$H$999,MATCH($A7,薬品マスタ!$A$2:$A$999,0))&"") | I7: =IF($A7="","",INDEX(薬品マスタ!$I$2:$I$999,MATCH($A7,薬品マスタ!$A$2:$A$999,0))&"") -> 1.抗菌抗薬 | J7: =IF($A7="","",INDEX(薬品マスタ!$T$2:$T$999,MATCH($A7,薬品マスタ!$A$2:$A$999,0))&"") -> 04.マクロライド系 | K7: =IF($A7="","",INDEX(薬品マスタ!$U$2:$U$999,MATCH($A7,薬品マスタ!$A$2:$A$999,0))&"") | L7: =IF($A7="","",INDEX(薬品マスタ!$J$2:$J$999,MATCH($A7,薬品マスタ!$A$2:$A$999,0))&"") -> クラリスロマイシンジョウ200mgタイショウ | M7: =IF($A7="","",INDEX(薬品マスタ!$M$2:$M$999,MATCH($A7,薬品マスタ!$A$2:$A$999,0))&"") | N7: =IF($A7="","",INDEX(薬品マスタ!$L$2:$L$999,MATCH($A7,薬品マスタ!$A$2:$A$999,0))&"") | O7: =IF($A7="","",INDEX(薬品マスタ!$N$2:$N$999,MATCH($A7,薬品マスタ!$A$2:$A$999,0))) -> 採用 | P7: =IF($A7="","",INDEX(薬品マスタ!$S$2:$S$999,MATCH($A7,薬品マスタ!$A$2:$A$999,0))&"") | Q7: ="【"&I7& IF(J7<>"","／"&J7,"")& IF(K7<>"","／"&K7,"")& "】" -> 【 1.抗菌抗薬／04.マクロライド系】 | R7: =IF(OR(I7<>I6,J7<>J6,K7<>K6),Q7,"") | S7: =IF($A7="","","■ "&$B7) -> ■ クラリスロマイシン錠200mg「大正」 | T7: =IF($A7="","", "成分："&$C7&CHAR(10)& "用法："&$D7&CHAR(10)& $E7& " "&$O7& " 懸濁："&$F7& " 粉砕："&$G7& " 脱カ："&$H7) -> 成分：クラリスロマイシン 用法：1回1錠、1日2回 内服薬 採用 懸濁：〇 粉砕：〇 脱カ：
A8: {=IFERROR(INDEX(薬品マスタ!$A$2:$A$999, SMALL(IF(薬品マスタ!$P$2:$P$999=1, ROW(薬品マスタ!$A$2:$A$999)-ROW(薬品マスタ!$A$2)+1), ROW(A7))),"")} -> DR0007 | B8: =IF($A8="","",INDEX(薬品マスタ!$B$2:$B$999,MATCH($A8,薬品マスタ!$A$2:$A$999,0))) -> ジスロマック錠250ｍｇ | C8: =IF($A8="","",INDEX(薬品マスタ!$C$2:$C$999,MATCH($A8,薬品マスタ!$A$2:$A$999,0))) -> アジスロマイシン | D8: =IF($A8="","",INDEX(薬品マスタ!$D$2:$D$999,MATCH($A8,薬品マスタ!$A$2:$A$999,0))) -> 1日1回500mg3日間 | E8: =IF($A8="","",INDEX(薬品マスタ!$E$2:$E$999,MATCH($A8,薬品マスタ!$A$2:$A$999,0))) -> 内服薬 | F8: =IF($A8="","",INDEX(薬品マスタ!$F$2:$F$999,MATCH($A8,薬品マスタ!$A$2:$A$999,0))&"") -> 〇 | G8: =IF($A8="","",INDEX(薬品マスタ!$G$2:$G$999,MATCH($A8,薬品マスタ!$A$2:$A$999,0))&"") -> △ | H8: =IF($A8="","",INDEX(薬品マスタ!$H$2:$H$999,MATCH($A8,薬品マスタ!$A$2:$A$999,0))&"") | I8: =IF($A8="","",INDEX(薬品マスタ!$I$2:$I$999,MATCH($A8,薬品マスタ!$A$2:$A$999,0))&"") -> 1.抗菌抗薬 | J8: =IF($A8="","",INDEX(薬品マスタ!$T$2:$T$999,MATCH($A8,薬品マスタ!$A$2:$A$999,0))&"") -> 04.マクロライド系 | K8: =IF($A8="","",INDEX(薬品マスタ!$U$2:$U$999,MATCH($A8,薬品マスタ!$A$2:$A$999,0))&"") | L8: =IF($A8="","",INDEX(薬品マスタ!$J$2:$J$999,MATCH($A8,薬品マスタ!$A$2:$A$999,0))&"") -> ジスロマックジョウ250mg | M8: =IF($A8="","",INDEX(薬品マスタ!$M$2:$M$999,MATCH($A8,薬品マスタ!$A$2:$A$999,0))&"") | N8: =IF($A8="","",INDEX(薬品マスタ!$L$2:$L$999,MATCH($A8,薬品マスタ!$A$2:$A$999,0))&"") | O8: =IF($A8="","",INDEX(薬品マスタ!$N$2:$N$999,MATCH($A8,薬品マスタ!$A$2:$A$999,0))) -> 採用 | P8: =IF($A8="","",INDEX(薬品マスタ!$S$2:$S$999,MATCH($A8,薬品マスタ!$A$2:$A$999,0))&"") | Q8: ="【"&I8& IF(J8<>"","／"&J8,"")& IF(K8<>"","／"&K8,"")& "】" -> 【 1.抗菌抗薬／04.マクロライド系】 | R8: =IF(OR(I8<>I7,J8<>J7,K8<>K7),Q8,"") | S8: =IF($A8="","","■ "&$B8) -> ■ ジスロマック錠250ｍｇ | T8: =IF($A8="","", "成分："&$C8&CHAR(10)& "用法："&$D8&CHAR(10)& $E8& " "&$O8& " 懸濁："&$F8& " 粉砕："&$G8& " 脱カ："&$H8) -> 成分：アジスロマイシン 用法：1日1回500mg3日間 内服薬 採用 懸濁：〇 粉砕：△ 脱カ：
A9: {=IFERROR(INDEX(薬品マスタ!$A$2:$A$999, SMALL(IF(薬品マスタ!$P$2:$P$999=1, ROW(薬品マスタ!$A$2:$A$999)-ROW(薬品マスタ!$A$2)+1), ROW(A8))),"")} -> DR0008 | B9: =IF($A9="","",INDEX(薬品マスタ!$B$2:$B$999,MATCH($A9,薬品マスタ!$A$2:$A$999,0))) -> ミノマイシンカプセル100mg | C9: =IF($A9="","",INDEX(薬品マスタ!$C$2:$C$999,MATCH($A9,薬品マスタ!$A$2:$A$999,0))) -> ミノサイクリン塩酸塩 | D9: =IF($A9="","",INDEX(薬品マスタ!$D$2:$D$999,MATCH($A9,薬品マスタ!$A$2:$A$999,0))) -> 初回100～200mg、以降12～24時間毎に100mg内服 | E9: =IF($A9="","",INDEX(薬品マスタ!$E$2:$E$999,MATCH($A9,薬品マスタ!$A$2:$A$999,0))) -> 内服薬 | F9: =IF($A9="","",INDEX(薬品マスタ!$F$2:$F$999,MATCH($A9,薬品マスタ!$A$2:$A$999,0))&"") -> 〇 | G9: =IF($A9="","",INDEX(薬品マスタ!$G$2:$G$999,MATCH($A9,薬品マスタ!$A$2:$A$999,0))&"") | H9: =IF($A9="","",INDEX(薬品マスタ!$H$2:$H$999,MATCH($A9,薬品マスタ!$A$2:$A$999,0))&"") -> 〇 | I9: =IF($A9="","",INDEX(薬品マスタ!$I$2:$I$999,MATCH($A9,薬品マスタ!$A$2:$A$999,0))&"") -> 1.抗菌抗薬 | J9: =IF($A9="","",INDEX(薬品マスタ!$T$2:$T$999,MATCH($A9,薬品マスタ!$A$2:$A$999,0))&"") -> 05.テトラサイクリン系 | K9: =IF($A9="","",INDEX(薬品マスタ!$U$2:$U$999,MATCH($A9,薬品マスタ!$A$2:$A$999,0))&"") | L9: =IF($A9="","",INDEX(薬品マスタ!$J$2:$J$999,MATCH($A9,薬品マスタ!$A$2:$A$999,0))&"") -> ミノマイシンカプセル | M9: =IF($A9="","",INDEX(薬品マスタ!$M$2:$M$999,MATCH($A9,薬品マスタ!$A$2:$A$999,0))&"") | N9: =IF($A9="","",INDEX(薬品マスタ!$L$2:$L$999,MATCH($A9,薬品マスタ!$A$2:$A$999,0))&"") | O9: =IF($A9="","",INDEX(薬品マスタ!$N$2:$N$999,MATCH($A9,薬品マスタ!$A$2:$A$999,0))) -> 採用 | P9: =IF($A9="","",INDEX(薬品マスタ!$S$2:$S$999,MATCH($A9,薬品マスタ!$A$2:$A$999,0))&"") | Q9: ="【"&I9& IF(J9<>"","／"&J9,"")& IF(K9<>"","／"&K9,"")& "】" -> 【 1.抗菌抗薬／05.テトラサイクリン系】 | R9: =IF(OR(I9<>I8,J9<>J8,K9<>K8),Q9,"") -> 【 1.抗菌抗薬／05.テトラサイクリン系】 | S9: =IF($A9="","","■ "&$B9) -> ■ ミノマイシンカプセル100mg | T9: =IF($A9="","", "成分："&$C9&CHAR(10)& "用法："&$D9&CHAR(10)& $E9& " "&$O9& " 懸濁："&$F9& " 粉砕："&$G9& " 脱カ："&$H9) -> 成分：ミノサイクリン塩酸塩 用法：初回100～200mg、以降12～24時間毎に100mg内服 内服薬 採用 懸濁：〇 粉砕： 脱カ：〇
A10: {=IFERROR(INDEX(薬品マスタ!$A$2:$A$999, SMALL(IF(薬品マスタ!$P$2:$P$999=1, ROW(薬品マスタ!$A$2:$A$999)-ROW(薬品マスタ!$A$2)+1), ROW(A9))),"")} -> DR0009 | B10: =IF($A10="","",INDEX(薬品マスタ!$B$2:$B$999,MATCH($A10,薬品マスタ!$A$2:$A$999,0))) -> レボフロキサシン錠500mg「DSPE」 | C10: =IF($A10="","",INDEX(薬品マスタ!$C$2:$C$999,MATCH($A10,薬品マスタ!$A$2:$A$999,0))) -> レボフロキサシン水和物 | D10: =IF($A10="","",INDEX(薬品マスタ!$D$2:$D$999,MATCH($A10,薬品マスタ!$A$2:$A$999,0))) -> 1日1回1錠 | E10: =IF($A10="","",INDEX(薬品マスタ!$E$2:$E$999,MATCH($A10,薬品マスタ!$A$2:$A$999,0))) -> 内服薬 | F10: =IF($A10="","",INDEX(薬品マスタ!$F$2:$F$999,MATCH($A10,薬品マスタ!$A$2:$A$999,0))&"") -> 〇 | G10: =IF($A10="","",INDEX(薬品マスタ!$G$2:$G$999,MATCH($A10,薬品マスタ!$A$2:$A$999,0))&"") -> 〇 | H10: =IF($A10="","",INDEX(薬品マスタ!$H$2:$H$999,MATCH($A10,薬品マスタ!$A$2:$A$999,0))&"") | I10: =IF($A10="","",INDEX(薬品マスタ!$I$2:$I$999,MATCH($A10,薬品マスタ!$A$2:$A$999,0))&"") -> 1.抗菌抗薬 | J10: =IF($A10="","",INDEX(薬品マスタ!$T$2:$T$999,MATCH($A10,薬品マスタ!$A$2:$A$999,0))&"") -> 06.ニューキノロン系 | K10: =IF($A10="","",INDEX(薬品マスタ!$U$2:$U$999,MATCH($A10,薬品マスタ!$A$2:$A$999,0))&"") | L10: =IF($A10="","",INDEX(薬品マスタ!$J$2:$J$999,MATCH($A10,薬品マスタ!$A$2:$A$999,0))&"") -> レボフロキサシンジョウ500ｍｇＤＥＳＰ | M10: =IF($A10="","",INDEX(薬品マスタ!$M$2:$M$999,MATCH($A10,薬品マスタ!$A$2:$A$999,0))&"") | N10: =IF($A10="","",INDEX(薬品マスタ!$L$2:$L$999,MATCH($A10,薬品マスタ!$A$2:$A$999,0))&"") | O10: =IF($A10="","",INDEX(薬品マスタ!$N$2:$N$999,MATCH($A10,薬品マスタ!$A$2:$A$999,0))) -> 採用 | P10: =IF($A10="","",INDEX(薬品マスタ!$S$2:$S$999,MATCH($A10,薬品マスタ!$A$2:$A$999,0))&"") | Q10: ="【"&I10& IF(J10<>"","／"&J10,"")& IF(K10<>"","／"&K10,"")& "】" -> 【 1.抗菌抗薬／06.ニューキノロン系】 | R10: =IF(OR(I10<>I9,J10<>J9,K10<>K9),Q10,"") -> 【 1.抗菌抗薬／06.ニューキノロン系】 | S10: =IF($A10="","","■ "&$B10) -> ■ レボフロキサシン錠500mg「DSPE」 | T10: =IF($A10="","", "成分："&$C10&CHAR(10)& "用法："&$D10&CHAR(10)& $E10& " "&$O10& " 懸濁："&$F10& " 粉砕："&$G10& " 脱カ："&$H10) -> 成分：レボフロキサシン水和物 用法：1日1回1錠 内服薬 採用 懸濁：〇 粉砕：〇 脱カ：
A11: {=IFERROR(INDEX(薬品マスタ!$A$2:$A$999, SMALL(IF(薬品マスタ!$P$2:$P$999=1, ROW(薬品マスタ!$A$2:$A$999)-ROW(薬品マスタ!$A$2)+1), ROW(A10))),"")} -> DR0010 | B11: =IF($A11="","",INDEX(薬品マスタ!$B$2:$B$999,MATCH($A11,薬品マスタ!$A$2:$A$999,0))) -> セフォセフ静注用1g | C11: =IF($A11="","",INDEX(薬品マスタ!$C$2:$C$999,MATCH($A11,薬品マスタ!$A$2:$A$999,0))) -> スルバクタムナトリウム/セフォペラゾンナトリウム | D11: =IF($A11="","",INDEX(薬品マスタ!$D$2:$D$999,MATCH($A11,薬品マスタ!$A$2:$A$999,0))) -> 1日1～2g、2回分割。静注または点滴静注。重症は1日4gまで。 | E11: =IF($A11="","",INDEX(薬品マスタ!$E$2:$E$999,MATCH($A11,薬品マスタ!$A$2:$A$999,0))) -> 注射剤 | F11: =IF($A11="","",INDEX(薬品マスタ!$F$2:$F$999,MATCH($A11,薬品マスタ!$A$2:$A$999,0))&"") | G11: =IF($A11="","",INDEX(薬品マスタ!$G$2:$G$999,MATCH($A11,薬品マスタ!$A$2:$A$999,0))&"") | H11: =IF($A11="","",INDEX(薬品マスタ!$H$2:$H$999,MATCH($A11,薬品マスタ!$A$2:$A$999,0))&"") | I11: =IF($A11="","",INDEX(薬品マスタ!$I$2:$I$999,MATCH($A11,薬品マスタ!$A$2:$A$999,0))&"") -> 1.抗菌抗薬 | J11: =IF($A11="","",INDEX(薬品マスタ!$T$2:$T$999,MATCH($A11,薬品マスタ!$A$2:$A$999,0))&"") -> 07.βラクタマーゼ阻害 | K11: =IF($A11="","",INDEX(薬品マスタ!$U$2:$U$999,MATCH($A11,薬品マスタ!$A$2:$A$999,0))&"") | L11: =IF($A11="","",INDEX(薬品マスタ!$J$2:$J$999,MATCH($A11,薬品マスタ!$A$2:$A$999,0))&"") -> セフォセフジョウチュウヨウ1g | M11: =IF($A11="","",INDEX(薬品マスタ!$M$2:$M$999,MATCH($A11,薬品マスタ!$A$2:$A$999,0))&"") | N11: =IF($A11="","",INDEX(薬品マスタ!$L$2:$L$999,MATCH($A11,薬品マスタ!$A$2:$A$999,0))&"") | O11: =IF($A11="","",INDEX(薬品マスタ!$N$2:$N$999,MATCH($A11,薬品マスタ!$A$2:$A$999,0))) -> 採用 | P11: =IF($A11="","",INDEX(薬品マスタ!$S$2:$S$999,MATCH($A11,薬品マスタ!$A$2:$A$999,0))&"") | Q11: ="【"&I11& IF(J11<>"","／"&J11,"")& IF(K11<>"","／"&K11,"")& "】" -> 【 1.抗菌抗薬／07.βラクタマーゼ阻害】 | R11: =IF(OR(I11<>I10,J11<>J10,K11<>K10),Q11,"") -> 【 1.抗菌抗薬／07.βラクタマーゼ阻害】 | S11: =IF($A11="","","■ "&$B11) -> ■ セフォセフ静注用1g | T11: =IF($A11="","", "成分："&$C11&CHAR(10)& "用法："&$D11&CHAR(10)& $E11& " "&$O11& " 懸濁："&$F11& " 粉砕："&$G11& " 脱カ："&$H11) -> 成分：スルバクタムナトリウム/セフォペラゾンナトリウム 用法：1日1～2g、2回分割。静注または点滴静注。重症は1日4gまで。 注射剤 採用 懸濁： 粉砕： 脱カ：
A12: {=IFERROR(INDEX(薬品マスタ!$A$2:$A$999, SMALL(IF(薬品マスタ!$P$2:$P$999=1, ROW(薬品マスタ!$A$2:$A$999)-ROW(薬品マスタ!$A$2)+1), ROW(A11))),"")} -> DR0011 | B12: =IF($A12="","",INDEX(薬品マスタ!$B$2:$B$999,MATCH($A12,薬品マスタ!$A$2:$A$999,0))) -> スルバシリン静注用1.5g | C12: =IF($A12="","",INDEX(薬品マスタ!$C$2:$C$999,MATCH($A12,薬品マスタ!$A$2:$A$999,0))) -> スルバクタムナトリウム/アンピシリンナトリウム | D12: =IF($A12="","",INDEX(薬品マスタ!$D$2:$D$999,MATCH($A12,薬品マスタ!$A$2:$A$999,0))) -> （肺炎、肺膿瘍、腹膜炎）1回3g、1日4回まで。（膀胱炎）1回1.5g、1日2回静注、点滴静注 | E12: =IF($A12="","",INDEX(薬品マスタ!$E$2:$E$999,MATCH($A12,薬品マスタ!$A$2:$A$999,0))) -> 注射剤 | F12: =IF($A12="","",INDEX(薬品マスタ!$F$2:$F$999,MATCH($A12,薬品マスタ!$A$2:$A$999,0))&"") | G12: =IF($A12="","",INDEX(薬品マスタ!$G$2:$G$999,MATCH($A12,薬品マスタ!$A$2:$A$999,0))&"") | H12: =IF($A12="","",INDEX(薬品マスタ!$H$2:$H$999,MATCH($A12,薬品マスタ!$A$2:$A$999,0))&"") | I12: =IF($A12="","",INDEX(薬品マスタ!$I$2:$I$999,MATCH($A12,薬品マスタ!$A$2:$A$999,0))&"") -> 1.抗菌抗薬 | J12: =IF($A12="","",INDEX(薬品マスタ!$T$2:$T$999,MATCH($A12,薬品マスタ!$A$2:$A$999,0))&"") -> 07.βラクタマーゼ阻害 | K12: =IF($A12="","",INDEX(薬品マスタ!$U$2:$U$999,MATCH($A12,薬品マスタ!$A$2:$A$999,0))&"") | L12: =IF($A12="","",INDEX(薬品マスタ!$J$2:$J$999,MATCH($A12,薬品マスタ!$A$2:$A$999,0))&"") -> スルバシリンジョウチュウヨウ1.5mg | M12: =IF($A12="","",INDEX(薬品マスタ!$M$2:$M$999,MATCH($A12,薬品マスタ!$A$2:$A$999,0))&"") | N12: =IF($A12="","",INDEX(薬品マスタ!$L$2:$L$999,MATCH($A12,薬品マスタ!$A$2:$A$999,0))&"") | O12: =IF($A12="","",INDEX(薬品マスタ!$N$2:$N$999,MATCH($A12,薬品マスタ!$A$2:$A$999,0))) -> 採用 | P12: =IF($A12="","",INDEX(薬品マスタ!$S$2:$S$999,MATCH($A12,薬品マスタ!$A$2:$A$999,0))&"") | Q12: ="【"&I12& IF(J12<>"","／"&J12,"")& IF(K12<>"","／"&K12,"")& "】" -> 【 1.抗菌抗薬／07.βラクタマーゼ阻害】 | R12: =IF(OR(I12<>I11,J12<>J11,K12<>K11),Q12,"") | S12: =IF($A12="","","■ "&$B12) -> ■ スルバシリン静注用1.5g | T12: =IF($A12="","", "成分："&$C12&CHAR(10)& "用法："&$D12&CHAR(10)& $E12& " "&$O12& " 懸濁："&$F12& " 粉砕："&$G12& " 脱カ："&$H12) -> 成分：スルバクタムナトリウム/アンピシリンナトリウム 用法：（肺炎、肺膿瘍、腹膜炎）1回3g、1日4回まで。（膀胱炎）1回1.5g、1日2回静注、点滴静注 注射剤 採用 懸濁： 粉砕： 脱カ：
A13: {=IFERROR(INDEX(薬品マスタ!$A$2:$A$999, SMALL(IF(薬品マスタ!$P$2:$P$999=1, ROW(薬品マスタ!$A$2:$A$999)-ROW(薬品マスタ!$A$2)+1), ROW(A12))),"")} -> DR0012 | B13: =IF($A13="","",INDEX(薬品マスタ!$B$2:$B$999,MATCH($A13,薬品マスタ!$A$2:$A$999,0))) -> セフタジジム静注用１g「VTRS」 | C13: =IF($A13="","",INDEX(薬品マスタ!$C$2:$C$999,MATCH($A13,薬品マスタ!$A$2:$A$999,0))) -> セフタジジム水和物 | D13: =IF($A13="","",INDEX(薬品マスタ!$D$2:$D$999,MATCH($A13,薬品マスタ!$A$2:$A$999,0))) -> 1日1～2g、2回分割。静注又は点滴静注。重症：1日4g、2回分割 | E13: =IF($A13="","",INDEX(薬品マスタ!$E$2:$E$999,MATCH($A13,薬品マスタ!$A$2:$A$999,0))) -> 注射剤 | F13: =IF($A13="","",INDEX(薬品マスタ!$F$2:$F$999,MATCH($A13,薬品マスタ!$A$2:$A$999,0))&"") | G13: =IF($A13="","",INDEX(薬品マスタ!$G$2:$G$999,MATCH($A13,薬品マスタ!$A$2:$A$999,0))&"") | H13: =IF($A13="","",INDEX(薬品マスタ!$H$2:$H$999,MATCH($A13,薬品マスタ!$A$2:$A$999,0))&"") | I13: =IF($A13="","",INDEX(薬品マスタ!$I$2:$I$999,MATCH($A13,薬品マスタ!$A$2:$A$999,0))&"") -> 1.抗菌抗薬 | J13: =IF($A13="","",INDEX(薬品マスタ!$T$2:$T$999,MATCH($A13,薬品マスタ!$A$2:$A$999,0))&"") -> 02.セフェム系 | K13: =IF($A13="","",INDEX(薬品マスタ!$U$2:$U$999,MATCH($A13,薬品マスタ!$A$2:$A$999,0))&"") -> 01.第３世代 | L13: =IF($A13="","",INDEX(薬品マスタ!$J$2:$J$999,MATCH($A13,薬品マスタ!$A$2:$A$999,0))&"") -> セフタジジムジョウチュウヨウVTRS | M13: =IF($A13="","",INDEX(薬品マスタ!$M$2:$M$999,MATCH($A13,薬品マスタ!$A$2:$A$999,0))&"") | N13: =IF($A13="","",INDEX(薬品マスタ!$L$2:$L$999,MATCH($A13,薬品マスタ!$A$2:$A$999,0))&"") | O13: =IF($A13="","",INDEX(薬品マスタ!$N$2:$N$999,MATCH($A13,薬品マスタ!$A$2:$A$999,0))) -> 採用 | P13: =IF($A13="","",INDEX(薬品マスタ!$S$2:$S$999,MATCH($A13,薬品マスタ!$A$2:$A$999,0))&"") | Q13: ="【"&I13& IF(J13<>"","／"&J13,"")& IF(K13<>"","／"&K13,"")& "】" -> 【 1.抗菌抗薬／02.セフェム系／01.第３世代】 | R13: =IF(OR(I13<>I12,J13<>J12,K13<>K12),Q13,"") -> 【 1.抗菌抗薬／02.セフェム系／01.第３世代】 | S13: =IF($A13="","","■ "&$B13) -> ■ セフタジジム静注用１g「VTRS」 | T13: =IF($A13="","", "成分："&$C13&CHAR(10)& "用法："&$D13&CHAR(10)& $E13& " "&$O13& " 懸濁："&$F13& " 粉砕："&$G13& " 脱カ："&$H13) -> 成分：セフタジジム水和物 用法：1日1～2g、2回分割。静注又は点滴静注。重症：1日4g、2回分割 注射剤 採用 懸濁： 粉砕： 脱カ：
... A600: {=IFERROR(INDEX(薬品マスタ!$A$2:$A$999, SMALL(IF(薬品マスタ!$P$2:$P$999=1, ROW(薬品マスタ!$A$2:$A$999)-ROW(薬品マスタ!$A$2)+1), ROW(A599))),"")} | B600: =IF($A600="","",INDEX(薬品マスタ!$B$2:$B$999,MATCH($A600,薬品マスタ!$A$2:$A$999,0))) | C600: =IF($A600="","",INDEX(薬品マスタ!$C$2:$C$999,MATCH($A600,薬品マスタ!$A$2:$A$999,0))) | D600: =IF($A600="","",INDEX(薬品マスタ!$D$2:$D$999,MATCH($A600,薬品マスタ!$A$2:$A$999,0))) | E600: =IF($A600="","",INDEX(薬品マスタ!$E$2:$E$999,MATCH($A600,薬品マスタ!$A$2:$A$999,0))) | F600: =IF($A600="","",INDEX(薬品マスタ!$F$2:$F$999,MATCH($A600,薬品マスタ!$A$2:$A$999,0))&"") | G600: =IF($A600="","",INDEX(薬品マスタ!$G$2:$G$999,MATCH($A600,薬品マスタ!$A$2:$A$999,0))&"") | H600: =IF($A600="","",INDEX(薬品マスタ!$H$2:$H$999,MATCH($A600,薬品マスタ!$A$2:$A$999,0))&"") | I600: =IF($A600="","",INDEX(薬品マスタ!$I$2:$I$999,MATCH($A600,薬品マスタ!$A$2:$A$999,0))&"") | J600: =IF($A600="","",INDEX(薬品マスタ!$T$2:$T$999,MATCH($A600,薬品マスタ!$A$2:$A$999,0))&"") | K600: =IF($A600="","",INDEX(薬品マスタ!$U$2:$U$999,MATCH($A600,薬品マスタ!$A$2:$A$999,0))&"") | L600: =IF($A600="","",INDEX(薬品マスタ!$J$2:$J$999,MATCH($A600,薬品マスタ!$A$2:$A$999,0))&"") | M600: =IF($A600="","",INDEX(薬品マスタ!$M$2:$M$999,MATCH($A600,薬品マスタ!$A$2:$A$999,0))&"") | N600: =IF($A600="","",INDEX(薬品マスタ!$L$2:$L$999,MATCH($A600,薬品マスタ!$A$2:$A$999,0))&"") | O600: =IF($A600="","",INDEX(薬品マスタ!$N$2:$N$999,MATCH($A600,薬品マスタ!$A$2:$A$999,0))) | P600: =IF($A600="","",INDEX(薬品マスタ!$S$2:$S$999,MATCH($A600,薬品マスタ!$A$2:$A$999,0))&"") | Q600: ="【"&I600& IF(J600<>"","／"&J600,"")& IF(K600<>"","／"&K600,"")& "】" -> 【】 | R600: =IF(OR(I600<>I599,J600<>J599,K600<>K599),Q600,"") | S600: =IF($A600="","","■ "&$B600) | T600: =IF($A600="","", "成分："&$C600&CHAR(10)& "用法："&$D600&CHAR(10)& $E600& " "&$O600& " 懸濁："&$F600& " 粉砕："&$G600& " 脱カ："&$H600)

Sheet 索引
A1: 薬品カナ | B1: 薬品名
A2: アイトロールジョウ20mg | B2: アイトロール錠20mg | C2: 21
A3: アエンカタンナンコウ10％ | B3: 亜鉛華単軟膏10％ | C3: 42
A4: アクテムラテンテキジョウチュウ200mg | B4: アクテムラ点滴静注200mg | C4: 8
A5: アクテムラテンテキジョウチュウ80mg | B5: アクテムラ点滴静注80mg | C5: 8
A6: アクテムラヒカチュウオートインジェクター162mg | B6: アクテムラ皮下注オートインジェクター162mg | C6: 8
A7: アクトシンナンコウ3％30g | B7: アクトシン軟膏3％30g | C7: 42
A8: アシクロビルテンテキジョウチュウエキ250mgニチイコウ | B8: アシクロビル点滴静注液250mg「日医工」 | C8: 3
A9: アジルサルタンODジョウ20mgキョウリン | B9: アジルサルタンOD錠20mg「杏林」 | C9: 21
A10: アスコルビンサンチュウ500mg | B10: アスコルビン酸注500mg「イセイ」 | C10: 14
A11: アスタットエキ１％ | B11: アスタット液1％ | C11: 3
A12: アスタットクリーム1% | B12: アスタットクリーム1％ | C12: 3
A13: アストミンジョウ10mg | B13: アストミン錠10mg | C13: 26
... A592: ワルファリンカリウムジョウ1mgNIG | B592: ワルファリンK錠1mg「NIG」 | C592: 18

Sheet 切り替え一覧
A1: 先発ID | B1: 先発名 | C1: 後発ID | D1: 後発名
A2: =IF(C2="","",INDEX(薬品マスタ!R$2:R$503,MATCH(C2,薬品マスタ!A$2:A$503,0))) -> DR0250 | B2: =IF(A2="","",INDEX(薬品マスタ!B$2:B$503,MATCH(A2,薬品マスタ!A$2:A$503,0))) -> エフィエント錠3.75mg | C2: {=IFERROR(INDEX(薬品マスタ!A$2:A$608,SMALL(IF(薬品マスタ!R$2:R$608<>"",ROW(薬品マスタ!A$2:A$608)-ROW(薬品マスタ!A$2)+1),ROW(A1))),"")} -> DR0251 | D2: =IF(C2="","",INDEX(薬品マスタ!B$2:B$608,MATCH(C2,薬品マスタ!A$2:A$608,0))) -> プラズグレル錠3.75mg「トーワ」

Sheet プルダウンマスタ
A1: 薬効分類（大）マスタ | B1: 項目 | C1: 薬効分類（中）マスタ | D1: 項目 | E1: 薬効分類（小）マスタ | G1: 区分マスタ | I1: 可否マスタ | K1: 採用 | M1: 先発/後発
A2: 1.抗菌抗薬 | B2: 抗菌薬 | C2: 01.広範囲ペニシリン系 | D2: セフェム系 | E2: 01.第３世代 | G2: 内服薬 | I2: 〇 | K2: 採用 | M2: 先発
A3: 2.抗ウィルス薬 | C3: 02.セフェム系 | D3: コロナウィルワクチン | E3: 01.ｍRNAワクチン | G3: 注射剤 | I3: × | K3: 限定 | M3: 後発
A4: 3.抗真菌薬 | C4: 03.アミノグリコシド系 | E4: 02.組換えタンパクワクチン | G4: 外用薬 | I4: △ | K4: 削除
A5: 4.抗寄生虫薬 | C5: 04.マクロライド系 | D5: 消毒 | E5: 01.ヨウ素系製剤
A6: 5.予防接種用薬 | C6: 05.テトラサイクリン系 | E6: 02.アルコール類
A7: 6.消毒薬 | C7: 06.ニューキノロン系 | E7: 03.四級アンモニウム塩
A8: 7.抗悪性腫瘍剤 | C8: 07.βラクタマーゼ阻害 | E8: 04.塩素系製剤
A9: 8.鎮痛薬 | C9: 08.カルバペネム系 | D9: 内分泌療法 | E9: 01.アロマターゼ阻害
A10: 9.副腎皮質ステロイド | C10: 09.経口ぺネム系 | E10: 02.抗アンドロゲン約
A11: 10.免疫疾患治療薬 | C11: 11.グリコペプチド系 | D11: NSAIDｓ | E11: 01.フェニル酢酸系
A12: 11.アレルギー疾患治療薬 | C12: 12.配合剤 | E12: 02.プロピオン酸系
A13: 12.糖尿病治療薬 | C13: 13.クロラムフェニコール系 | E13: 03.オキシカム系
A14: 13.高脂血症治療薬 | B14: 抗真菌薬 | C14: 02.ポリペプチド系 | E14: 04.コキシブ系
A15: 14.高尿酸血症治療薬 | B15: 抗ウィルス薬 | C15: 01.インフルエンザ | D15: 免疫抑制 | E15: 01.プリン代謝拮抗薬
A16: 15.女性ホルモン製剤 | C16: 02.帯状疱疹 | E16: 02.葉酸代謝拮抗薬
A17: 16.男性ホルモン製剤 | C17: 03.新型コロナウィルス | E17: 03.ピリミジン合成阻害薬
A18: 17.代謝異常症治療薬 | B18: 抗寄生虫 | C18: 01.抗線虫 | E18: 04.アルキル化薬
A19: 18.甲状腺疾患治療薬 | C19: 02.抗原虫 | E19: 05.リンパ球増殖抑制薬
A20: 19.骨・カルシウム代謝薬 | B20: 予防接種 | C20: 01.トキソイド | E20: 06.細胞増殖シグナル阻害薬
A21: 20.ビタミン・輸液 | C21: 02.弱毒生ワクチン | E21: 07.カルシニューリン阻害
A22: 21.造血薬 | C22: 03.不活化ワクチン | E22: 08.JAK阻害薬
A23: 22.止血剤 | C23: 04.コロナウィルスワクチン | D23: 生物学的製剤 | E23: 01.TNFα阻害薬
A24: 23.抗血栓薬 | B24: 消毒薬 | C24: 01.高水準 | E24: 02.IL-6阻害薬
A25: 24.高血圧治療薬 | C25: 02.中水準 | E25: 03.IL-1阻害薬
A26: 25.狭心症治療薬 | C26: 03.低水準 | E26: 04.T細胞共刺激調節薬
A27: 26.抗不整脈薬 | B27: 抗悪性腫瘍剤 | C27: 01.内分泌療法薬 | E27: 05.IL-2阻害薬
A28: 27.心不全治療薬、昇圧薬 | B28: 鎮痛薬 | C28: 01.アセトアミノフェン | E28: 06.B細胞標的薬
A29: 28.血管拡張薬・肺高血圧治療薬 | C29: 02.アセトアミノフェン配合剤 | E29: 07.IL-12/23阻害薬
A30: 29.利尿薬 | C30: 03.NSAIDｓ | E30: 08.IL-17阻害薬
A31: 30.気管支喘息治療薬、COPD治療薬 | C31: 04.経皮用剤 | E31: 09.IL-23阻害薬
A32: 31.鎮咳・去痰薬 | C32: 05.外皮用配合剤 | E32: 10.Ⅰ型インターフェロン阻害薬
A33: 32.上部消化管疾患治療薬 | C33: 06.神経障害性疼痛緩和薬 | D33: ヒスタミン拮抗 | E33: 01.第2世代
A34: 33.下部消化管疾患治療薬 | C34: 07.鎮痛補助薬 | E34: 02.第1世代
A35: 34.痔疾患治療薬 | B35: 免疫疾患治療薬 | C35: 01.免疫調節薬 | D35: 糖尿配合 | E35: 01.その他
A36: 35.肝疾患治療薬 | C36: 02.免疫抑制薬 | E36: 02.DPP-4/BG
A37: 36.胆道疾患治療薬 | C37: 03.生物学的製剤 | E37: 03.DPP-4/SGLT2
A38: 37.膵疾患治療薬 | B38: 抗アレルギー | C38: 01.ヒスタミン受容体拮抗薬 | E38: 04.インスリン/GLP-1
A39: 38.抗精神病薬・抗うつ薬 | C39: 02.ロイコトリエン受容体拮抗薬 | D39: インスリン | E39: 01.超速攻型
A40: 39.抗不安薬 | C40: 03.メディエーター遊離抑制薬 | E40: 02.速攻型
...

Sheet 改訂履歴用プルダウンマスタ
A1: 変更区分 | B1: 変更理由 | C1: 担当者 | D1: 確認者
A2: 新規採用 | B2: 新規採用 | C2: 薬局長 | D2: 薬局長
A3: 採用中止 | B3: 後発切替 | C3: DI担当 | D3: DI担当
A4: 変更 | B4: メーカー変更
A5: 切替 | B5: 販売中止
A6: 訂正 | B6: 採用整理
B7: 情報更新
B8: 入力修正
